
<robot name="dh">

<material name="blue">
    <color rgba="0 0 0.8 1"/>
</material>

<material name="white">
    <color rgba="1 1 1 1"/>
</material>

<joint name="joint1" type="continuous">
	<parent link="floor"/>
	<child link="link1"/>
	<origin xyz="0 0 0.5" rpy="0 0 0" />
	
</joint>


<joint name="joint2" type="continuous">
	<parent link="link1"/>
	<child link="link2"/>
	<origin xyz="0 0.5 0.5" rpy="-1.57 0 0" />
	
</joint>

<joint name="joint3" type="continuous">
	<parent link="link2"/>
	<child link="link3"/>
	<origin xyz="0 0 1" rpy="0 0 0" />
	
</joint>



</robot>
