
<robot name="dh">

<link name="link1">
    <visual>
      <geometry>
        <cylinder length="0.6" radius="0.2"/>
      </geometry>
    </visual>
  </link>
<link name="link2">
    <visual>
      <geometry>
        <cylinder length="0.6" radius="0.2"/>
      </geometry>
    </visual>
  </link>
<link name="link3">
    <visual>
      <geometry>
        <cylinder length="0.6" radius="0.2"/>
      </geometry>
    </visual>
  </link>
<link name="link4" />


<joint name="joint1" type="continuous">
	<parent link="link1"/>
	<child link="link2"/>
	<origin xyz="0 0 0" rpy="0 0 0" />
</joint>

<joint name="joint2" type="continuous">
	<parent link="link2"/>
	<child link="link3"/>
	<origin xyz="5 0 0" rpy="-1.57 0 0" />	
</joint>
<joint name="joint3" type="continuous">
	<parent link="link3"/>
	<child link="link4"/>
	<origin xyz="5 0 5" rpy="0 0 0" />	
</joint>



</robot>
